Workbook

Sheet main
L2: Q425 | M2: 2026 | N2: =+M2+1 -> 2027 | O2: =+N2+1 -> 2028 | P2: =+O2+1 -> 2029 | Q2: =+P2+1 -> 2030
K3: Price | L3: 100 | M3: =+L3*1.1 -> 110 | N3: =+M3*1.1 -> 121 | O3: =+N3*1.1 -> 133.1 | P3: =+O3*1.1 -> 146.41 | Q3: =+P3*1.1 -> 161.051
K4: Shares | L4: 54.2 | M4: =+L4*1.02 -> 55.284 | N4: =+M4*1.02 -> 56.38968 | O4: =+N4*1.02 -> 57.517474 | P4: =+O4*1.02 -> 58.667823 | Q4: =+P4*1.02 -> 59.84118
K5: MC | L5: =+L4*L3 -> 5420 | M5: =+M4*M3 -> 6081.24 | N5: =+N4*N3 -> 6823.1513 | O5: =+O4*O3 -> 7655.5757 | P5: =+P4*P3 -> 8589.556 | Q5: =+Q4*Q3 -> 9637.4818
K6: Cash | L6: 535.5 | M6: =+L6*0.99 -> 530.145 | N6: =+M6*0.99 -> 524.84355 | O6: =+N6*0.99 -> 519.59511 | P6: =+O6*0.99 -> 514.39916 | Q6: =+P6*0.99 -> 509.25517
K7: Debt | L7: =60.9+409 -> 469.9 | M7: =+L7*1.03 -> 483.997 | N7: =+M7*1.03 -> 498.51691 | O7: =+N7*1.03 -> 513.47242 | P7: =+O7*1.03 -> 528.87659 | Q7: =+P7*1.03 -> 544.74289
K8: EV | L8: =+L5-L6+L7 -> 5354.4 | M8: =+M5-M6+M7 -> 6035.092 | N8: =+N5-N6+N7 -> 6796.8246 | O8: =+O5-O6+O7 -> 7649.453 | P8: =+P5-P6+P7 -> 8604.0334 | Q8: =+Q5-Q6+Q7 -> 9672.9695
L9: -5354 | M9: 0 | N9: 0 | O9: 0 | P9: 0 | Q9: =+Q8 -> 9672.9695
K11: Rev | R11: =+model!T3*1.2 -> 9089.88
K12: E | L12: =+model!T12 -> 274.9 | M12: =+L12*1.25 -> 343.625 | N12: =+M12*1.25 -> 429.53125 | O12: =+N12*1.2 -> 515.4375 | P12: =+O12*1.2 -> 618.525 | Q12: =+P12*1.15 -> 711.30375 | R12: =+Q12*0.98 -> 697.07767 | S12: =+R12*0.98 -> 683.13612 | T12: =+S12*0.98 -> 669.4734 | U12: =+T12*0.98 -> 656.08393 | V12: =+U12*0.98 -> 642.96225 | W12: =+V12*0.98 -> 630.10301 | X12: =+W12*0.98 -> 617.50095 | Y12: =+X12*0.98 -> 605.15093 | ... AI12: =+AH12*0.98 -> 494.45237
M13: =+M12/L12-1 -> 0.25 | N13: =+N12/M12-1 -> 0.25 | O13: =+O12/N12-1 -> 0.2 | P13: =+P12/O12-1 -> 0.2 | Q13: =+Q12/P12-1 -> 0.15
K14: EV/E | L14: =+L8/L12 -> 19.477628 | M14: =+M8/M12 -> 17.563018 | N14: =+N8/N12 -> 15.823819 | O14: =+O8/O12 -> 14.840699 | P14: =+P8/P12 -> 13.910567 | Q14: =+Q8/Q12 -> 13.598929
K15: EPS | L15: =+L12/L4 -> 5.0719557 | M15: =+M12/M4 -> 6.215632 | N15: =+N12/N4 -> 7.6171961 | O15: =+O12/O4 -> 8.9614072 | P15: =+P12/P4 -> 10.542832 | Q15: =+Q12/Q4 -> 11.886526
K16: P/E | L16: =+L3/L15 -> 19.71626 | M16: =+M3/M15 -> 17.697315 | N16: =+N3/N15 -> 15.88511 | O16: =+O3/O15 -> 14.852578 | P16: =+P3/P15 -> 13.887161 | Q16: =+Q3/Q15 -> 13.549038
K18: IRR | L18: =+IRR(L9:Q9) -> 0.1255798
K19: VAL | L19: =+NPV(0.08,M12:AI12)-L6+L7 -> 5887.6399
K20: Per Share | L20: =+L19/L4 -> 108.62804

Sheet model
C2: Q14 | D2: Q224 | E2: Q324 | F2: Q424 | G2: Q125 | H2: Q225 | I2: Q325 | J2: Q425 | O2: 2020 | P2: 2021 | Q2: 2022 | R2: =+Q2+1 -> 2023 | S2: =+R2+1 -> 2024 | T2: =+S2+1 -> 2025 | U2: =+T2+1 -> 2026 | V2: =+U2+1 -> 2027 | W2: =+V2+1 -> 2028 | X2: =+W2+1 -> 2029 | Y2: =+X2+1 -> 2030 | Z2: =+Y2+1 -> 2031
B3: Revenue | J3: 1559.9 | K3: =+J3*4 -> 6239.6 | O3: 3491 | P3: 3497 | Q3: 4420.6 | R3: 5715.3 | S3: 6399.8 | T3: 7574.9
B4: COGS | J4: 1425.2 | Q4: 3963.7 | R4: 5127.8 | S4: 5663.6 | T4: 6761.8
B5: Gross Profit | J5: =+J3-J4 -> 134.7 | Q5: =+Q3-Q4 -> 456.9 | R5: =+R3-R4 -> 587.5 | S5: =+S3-S4 -> 736.2 | T5: =+T3-T4 -> 813.1
B6: SGA | J6: 105 | Q6: 281.6 | R6: 328.7 | S6: 383.3 | T6: 399.2
B7: Other | J7: 4.5 | Q7: 0 | R7: 5.7 | S7: 2.5 | T7: 2.4
B8: Operating Income | J8: =+J5-J6-J7 -> 25.2 | Q8: =+Q5-Q6-Q7 -> 175.3 | R8: =+R5-R6-R7 -> 253.1 | S8: =+S5-S6-S7 -> 350.4 | T8: =+T5-T6-T7 -> 411.5
B9: Interest Expense | J9: 0.1 | Q9: -36.1 | R9: =1.1+1.6-78.6 -> -75.9 | S9: =2.7-0.1-65.3 -> -62.7 | T9: =-0.1+1.3-28.7 -> -27.5
B10: Pretax | J10: =+J8+J9 -> 25.3 | Q10: =+Q8+Q9 -> 139.2 | R10: =+R8+R9 -> 177.2 | S10: =+S8+S9 -> 287.7 | T10: =+T8+T9 -> 384
B11: Tax | J11: -2.5 | Q11: -26.3 | R11: -51.5 | S11: -74 | T11: -109.1
B12: NI | J12: =+J10+J11 -> 22.8 | O12: 105 | P12: 115.7 | Q12: =+Q10+Q11 -> 112.9 | R12: =+R10+R11 -> 125.7 | S12: =+S10+S11 -> 213.7 | T12: =+T10+T11 -> 274.9 | U12: =+T12*1.05 -> 288.645 | V12: =+U12*1.05 -> 303.07725 | W12: =+V12*1.05 -> 318.23111 | X12: =+W12*1.05 -> 334.14267 | Y12: =+X12 -> 334.14267 | Z12: =+Y12 -> 334.14267 | AA12: =+Z12*0.98 -> 327.45981 | AB12: =+AA12*0.98 -> 320.91062 | AC12: =+AB12*0.98 -> 314.49241 | AD12: =+AC12*0.98 -> 308.20256 | AE12: =+AD12*0.98 -> 302.03851 | AF12: =+AE12*0.98 -> 295.99774 | AG12: =+AF12*0.98 -> 290.07778 | AH12: =+AG12*0.98 -> 284.27623 | ... AX12: =+AW12*0.98 -> 205.75848
B13: EPS | R13: 53.3 | S13: 53.6 | T13: 54
B14: Shares
B16: Revenue Growth | P16: =+P3/O3-1 -> 0.0017187052 | Q16: =+Q3/P3-1 -> 0.2641121 | R16: =+R3/Q3-1 -> 0.29287879 | S16: =+S3/R3-1 -> 0.11976624 | T16: =+T3/S3-1 -> 0.18361511 | V16: Val | W16: =+NPV(0.08,U12:AX12) -> 3326.4737
B17: Gross Margin | R17: =+R5/Q5-1 -> 0.28583935 | S17: =+S5/R5-1 -> 0.25310638 | T17: =+T5/S5-1 -> 0.10445531 | W17: =+W16-main!L6+main!L7 -> 3260.8737
B18: Operating Margin | R18: =+R8/Q8-1 -> 0.44381061 | S18: =+S8/R8-1 -> 0.38443303 | T18: =+T8/S8-1 -> 0.17437215 | W18: =+W17/main!L4 -> 60.163722
B19: Tax Rate | R19: =+R11/R10 -> -0.29063205 | S19: =+S11/S10 -> -0.25721237 | T19: =+T11/T10 -> -0.28411458
B20: NI Growth | P20: =+P12/O12-1 -> 0.10190476 | Q20: =+Q12/P12-1 -> -0.024200519 | R20: =+R12/Q12-1 -> 0.11337467 | S20: =+S12/R12-1 -> 0.70007955 | T20: =+T12/S12-1 -> 0.28638278
B22: Cash | S22: 455.8 | T22: =+main!L6 -> 535.5
B23: AR | S23: 834.4 | T23: 723.4
B24: Contracts | S24: 773.7 | T24: 936.9
B25: OCA | S25: 95.6 | T25: 137.8
B26: PPE | S26: 488.2 | T26: 531.2
B27: Leases | S27: 461 | T27: 488.9
B28: Intangibles | S28: =207.9+856.9 -> 1064.8 | T28: =190.2+856.9 -> 1047.1
B29: OLTA | S29: 22.4 | T29: 7
B30: Assets | S30: =+SUM(S22:S29) -> 4195.9 | T30: =+SUM(T22:T29) -> 4407.8
B32: Debt | S32: =74.6+660.2 -> 734.8 | T32: =+main!L7 -> 469.9
B33: AP | S33: 624.3 | T33: 744.3
B34: Contracts | S34: 617.4 | T34: 633.6
B35: Accrued | S35: 350.1 | T35: 405.4
B36: Dividends | S36: 4.3 | T36: 4.3
B37: Leases | S37: 333.4 | T37: 325.6
B38: DT | S38: 64 | T38: 71.4
B39: ONCLL | S39: 58.1 | T39: 72.3
B40: Liabilities | S40: =+SUM(S32:S39) -> 2786.4 | T40: =+SUM(T32:T39) -> 2726.8
B42: S/E | S42: =+S30-S40 -> 1409.5 | T42: =+T30-T40 -> 1681
B43: L+S/E | S43: =+S40+S42 -> 4195.9 | T43: =+T40+T42 -> 4407.8
B45: ROA | S45: =+S12/S30 -> 0.05093067 | T45: =+T12/T30 -> 0.062366714
B46: ROE | S46: =+S12/S42 -> 0.15161405 | T46: =+T12/T42 -> 0.16353361
...
